<?xml version="1.0"?>
<robot name="my_robot">
  
  <!-- Malzeme tanımları -->
  <material name="blue">
    <color rgba="0 0 1 1"/>
  </material>
  <material name="black">
    <color rgba="0 0 0 1"/>
  </material>

  <!-- Base Link (Robot Gövdesi) -->
  <link name="base_link">
    <visual>
      <geometry>
        <box size="0.5 0.5 0.2"/> <!-- Gövde boyutları -->
      </geometry>
      <material name="blue"/>
    </visual>
    <collision>
      <geometry>
        <box size="0.5 0.5 0.2"/> <!-- Çarpışma için aynı boyut -->
      </geometry>
    </collision>
  </link>

  <!-- Sol Tekerlek -->
  <link name="left_wheel">
    <visual>
      <geometry>
        <cylinder length="0.1" radius="0.05"/> <!-- Sol tekerlek boyutları -->
      </geometry>
      <material name="black"/>
    </visual>
    <collision>
      <geometry>
        <cylinder length="0.1" radius="0.05"/> <!-- Çarpışma için aynı boyut -->
      </geometry>
    </collision>
  </link>

  <!-- Sağ Tekerlek -->
  <link name="right_wheel">
    <visual>
      <geometry>
        <cylinder length="0.1" radius="0.05"/> <!-- Sağ tekerlek boyutları -->
      </geometry>
      <material name="black"/>
    </visual>
    <collision>
      <geometry>
        <cylinder length="0.1" radius="0.05"/> <!-- Çarpışma için aynı boyut -->
      </geometry>
    </collision>
  </link>

  <!-- Sol Tekerlek Ekinetik Eklem (Dönme Hareketi İçin) -->
  <joint name="left_wheel_joint" type="continuous">
    <parent link="base_link"/>
    <child link="left_wheel"/>
    <origin xyz="-0.2 0.3 0"/>
    <axis xyz="0 0 1"/>
  </joint>

  <!-- Sağ Tekerlek Ekinetik Eklem (Dönme Hareketi İçin) -->
  <joint name="right_wheel_joint" type="continuous">
    <parent link="base_link"/>
    <child link="right_wheel"/>
    <origin xyz="0.2 0.3 0"/>
    <axis xyz="0 0 1"/>
  </joint>

</robot>
